# 范围for语句
```cpp
for(declaration : expression){
    statement;
}

vector<int> v = {0,1,2,3};

for( auto &r : v){
    r *= 2;
}

for(auto beg = v.begin(), end = v.end(); ++beg){
    auto &r = *beg;
    r *= 2;
}
```

# `try语句块`和异常处理
## throw语句
- 程序的异常检测部分使用`throw`表达式**引发**一个异常
```cpp
#include <stdexceot>//为runtime_error提供头文件67

if(item1.isbn() != item2.isbn()){
    throw runtime_error("Dara must refer to same ISBN");
}
```

## try语句块
- 通用语法：
```cpp
try {
    program-statement
} catch(exception-declaration){
    handler-statement
} catch(exception-declaration){
    handler-statement
} //..
```
- `try`紧接着的块运行，若抛出错误则通过catch来定位并在相关catch紧接着的块中处理
- 如无catch对应，程序将转到名为`terminate的标准库函数`
- 程序无try语句，异常也会转到terminate处理
- catch其实就是在terminate之前截胡处理错误

- **编写异常安全**的函数十分困难
